<!DOCTYPE html>
<html lang="en">
<head>
	<meta charset="UTF-8">
	<title>Document</title>
</head>
<body>
	<script>
		/*
			catch是then(null,reject)或者then(undefined,reject)的别名
			用于注册Promise对象状态为rejected时的回调函数

			Promise 对象的错误具有“冒泡”性质，会一直向后传递，直到被捕获为止。
			也就是说，错误总是会被下一个catch语句捕获。

			错误信息通过catch捕捉  就不会通过浏览器报错

		*/
		/*new Promise(function(resolve,reject){
    		reject();
		}).then(null,function(){
			console.log("error");
		}) */
		/*
			new Promise(function(resolve,reject){
	    		resolve();
			}).then(function(){
				console.log("resolve");
				resolve();
			},function(){
				console.log("error");
			})
			通过then的onRejected(第二个参数)回调函数无法捕捉到then的onFulfilled(第一个参数)回调函数的错误
			如果通过.catch就可以捕捉到 因为then方法返回一个新的Promise对象 同时是链式调用 catch 所以 catch可以捕捉到then运行时抛出的错误  
			并把错误信息通过参数的形式传递给catch的回调函数
		*/

		new Promise(function(resolve,reject){
			resolve();
		}).then(function(){
			new Promise();
		}).catch(function(value){
			console.log("error!!!"+value);
		})

		new Promise(function(resolve,reject){
			reject("catch");
		}).then(function(){//then方法内部可能就是看状态 如果是reject 那么就调用第二个参数的回调函数 如果没有这个回调函数就原封不动的return回这个Promise
			new Promise();
		}).catch(function(value){
			console.log("Promise 对象的错误具有冒泡性质，会一直向后传递，直到被捕获为止。也就是说，错误总是会被下一个catch语句捕获。");
		})

		new Promise(function(resolve,reject){
			return x
		}).catch(function(value){ //错误信息通过catch捕捉  就不会通过浏览器报错
			console.log(value)
		})

		new Promise(function(){
			return x//打印错误 提示 x is not defined 但是不会退出进程 终止脚本进行 Promise内部错误 不会影响到Promise外部的代码执行
		})
// 		还是正常输出了1  
		console.log(1);

		var p = new Promise(function(resolve,reject){
			reject();//这里并没有设置对应的回调函数 所以报错 但是没有停止进程 验证了Promise内部错误 不会影响到Promise外部的代码执行
		})
		console.log(p.then());//因为P是reject状态 内部并没有设置回调函数处理 所以原封不动的返回p这个实例
		 
		new Promise(function(resolve,reject){
			reject();
		}).then(function(){
			console.log("then");
		}).catch(function(){
			console.log("catch");//因为上面Promise实例调用的then方法里面没有设置reject对应的回调函数 所以原封不动的返回了那么实例
			// 所以执行了这里的catch  好像冒泡一样  直到被捕获
		})
	</script>
</body>
</html>